<?xml version="1.0" encoding="UTF-8"?>
<!-- Generated by org.testng.reporters.JUnitReportReporter -->
<testsuite hostname="LAPTOP-D34DC2QJ" name="com.busyqa.batch16.uitests.testCases.TC01_LoginTest" tests="5" failures="0" timestamp="31 Jul 2020 00:54:55 GMT" time="21.048" errors="1">
  <testcase name="loginTest03" time="2.033" classname="com.busyqa.batch16.uitests.testCases.TC01_LoginTest"/>
  <testcase name="loginTest01" time="10.085" classname="com.busyqa.batch16.uitests.testCases.TC01_LoginTest"/>
  <testcase name="failed_TC1" time="0.316" classname="com.busyqa.batch16.uitests.testCases.TC01_LoginTest">
    <error type="java.lang.AssertionError" message="expected [true] but found [false]">
      <![CDATA[java.lang.AssertionError: expected [true] but found [false]
	at org.testng.Assert.fail(Assert.java:94)
	at org.testng.Assert.failNotEquals(Assert.java:494)
	at org.testng.Assert.assertEquals(Assert.java:123)
	at org.testng.Assert.assertEquals(Assert.java:286)
	at org.testng.Assert.assertEquals(Assert.java:296)
	at com.busyqa.batch16.uitests.testCases.TC01_LoginTest.failed_TC1(TC01_LoginTest.java:175)
	at sun.reflect.NativeMethodAccessorImpl.invoke0(Native Method)
	at sun.reflect.NativeMethodAccessorImpl.invoke(NativeMethodAccessorImpl.java:62)
	at sun.reflect.DelegatingMethodAccessorImpl.invoke(DelegatingMethodAccessorImpl.java:43)
	at java.lang.reflect.Method.invoke(Method.java:498)
	at org.testng.internal.MethodInvocationHelper.invokeMethod(MethodInvocationHelper.java:84)
	at org.testng.internal.Invoker.invokeMethod(Invoker.java:714)
	at org.testng.internal.Invoker.invokeTestMethod(Invoker.java:901)
	at org.testng.internal.Invoker.invokeTestMethods(Invoker.java:1231)
	at org.testng.internal.TestMethodWorker.invokeTestMethods(TestMethodWorker.java:127)
	at org.testng.internal.TestMethodWorker.run(TestMethodWorker.java:111)
	at org.testng.TestRunner.privateRun(TestRunner.java:767)
	at org.testng.TestRunner.run(TestRunner.java:617)
	at org.testng.SuiteRunner.runTest(SuiteRunner.java:348)
	at org.testng.SuiteRunner.access$000(SuiteRunner.java:38)
	at org.testng.SuiteRunner$SuiteWorker.run(SuiteRunner.java:382)
	at org.testng.internal.thread.ThreadUtil$2.call(ThreadUtil.java:64)
	at java.util.concurrent.FutureTask.run(FutureTask.java:266)
	at java.util.concurrent.ThreadPoolExecutor.runWorker(ThreadPoolExecutor.java:1149)
	at java.util.concurrent.ThreadPoolExecutor$Worker.run(ThreadPoolExecutor.java:624)
	at java.lang.Thread.run(Thread.java:748)
]]>
    </error>
  </testcase> <!-- failed_TC1 -->
  <testcase name="loginTest02" time="2.084" classname="com.busyqa.batch16.uitests.testCases.TC01_LoginTest"/>
  <testcase name="loginTest04" time="6.530" classname="com.busyqa.batch16.uitests.testCases.TC01_LoginTest"/>
</testsuite> <!-- com.busyqa.batch16.uitests.testCases.TC01_LoginTest -->
